Workbook

Sheet ammo
A1: shells | B1: max | C1: ammo | F1: =_xlfn.TEXTJOIN("_","TRUE",$B1:$E1) -> max_ammo | H1: 100
A2: nailgun | B2: max | C2: ammo | F2: =_xlfn.TEXTJOIN("_","TRUE",$B2:$E2) -> max_ammo | H2: 200
A3: rocketlauncher | B3: max | C3: ammo | F3: =_xlfn.TEXTJOIN("_","TRUE",$B3:$E3) -> max_ammo | H3: 100
A4: cells | B4: max | C4: ammo | F4: =_xlfn.TEXTJOIN("_","TRUE",$B4:$E4) -> max_ammo | H4: 100

Sheet base
A1: axe | B1: attack | C1: delay | F1: =_xlfn.TEXTJOIN("_","TRUE",$B1:$E1) -> attack_delay | H1: 0.49 | I1: {=_xlfn._xlws.SORT(_xlfn.UNIQUE(_xlfn._xlws.FILTER($A:$A,$A:$A<>"")))} -> axe | J1: {=_xlfn._xlws.SORT(_xlfn.UNIQUE(_xlfn._xlws.FILTER($F:$F,$F:$F<>"")))} -> ammo_cost
A2: axe | B2: dmg | F2: =_xlfn.TEXTJOIN("_","TRUE",$B2:$E2) -> dmg | H2: 24 | I2: grenadelauncher | J2: ammo_type
A3: nailgun | B3: fn | C3: fire | F3: =_xlfn.TEXTJOIN("_","TRUE",$B3:$E3) -> fn_fire | H3: nail | I3: lightninggun | J3: attack_delay
A4: nailgun | B4: fn | C4: spread | F4: =_xlfn.TEXTJOIN("_","TRUE",$B4:$E4) -> fn_spread | H4: oval | I4: nailgun | J4: bounce
A5: nailgun | B5: ammo | C5: type | F5: =_xlfn.TEXTJOIN("_","TRUE",$B5:$E5) -> ammo_type | H5: nails | I5: perforator | J5: clip_size
A6: nailgun | B6: ammo | C6: cost | F6: =_xlfn.TEXTJOIN("_","TRUE",$B6:$E6) -> ammo_cost | H6: 1 | I6: rocketlauncher | J6: dmg
A7: nailgun | B7: attack | C7: delay | F7: =_xlfn.TEXTJOIN("_","TRUE",$B7:$E7) -> attack_delay | H7: 0.09 | I7: shotgun | J7: dmg_splash
A8: nailgun | B8: dmg | F8: =_xlfn.TEXTJOIN("_","TRUE",$B8:$E8) -> dmg | H8: 9 | I8: soldiershotgun | J8: fn_fire
A9: nailgun | B9: dmg | C9: splash | F9: =_xlfn.TEXTJOIN("_","TRUE",$B9:$E9) -> dmg_splash | H9: 0 | I9: supershotgun | J9: fn_origin
A10: nailgun | B10: spread | F10: =_xlfn.TEXTJOIN("_","TRUE",$B10:$E10) -> spread | H10: '0 0 0' | J10: fn_spread
A11: nailgun | B11: sfx | C11: fire | F11: =_xlfn.TEXTJOIN("_","TRUE",$B11:$E11) -> sfx_fire | H11: weapons/rocket1i.wav | J11: impart_vel
A12: nailgun | B12: vel | F12: =_xlfn.TEXTJOIN("_","TRUE",$B12:$E12) -> vel | H12: 1996 0 0' | J12: origin_angle_change
A13: nailgun | B13: fn | C13: origin | F13: =_xlfn.TEXTJOIN("_","TRUE",$B13:$E13) -> fn_origin | H13: circle | J13: origin_angle_offset
A14: nailgun | B14: origin | C14: base | D14: offset | F14: =_xlfn.TEXTJOIN("_","TRUE",$B14:$E14) -> origin_base_offset | H14: '0 11 16' | J14: origin_base_offset
A15: nailgun | B15: origin | C15: angle | D15: change | F15: =_xlfn.TEXTJOIN("_","TRUE",$B15:$E15) -> origin_angle_change | H15: 180 | J15: origin_circle_radius
A16: nailgun | B16: origin | C16: angle | D16: offset | F16: =_xlfn.TEXTJOIN("_","TRUE",$B16:$E16) -> origin_angle_offset | H16: 0 | J16: penetration_limit
A17: nailgun | B17: origin | C17: circle | D17: radius | F17: =_xlfn.TEXTJOIN("_","TRUE",$B17:$E17) -> origin_circle_radius | H17: 2.5 | J17: punch_angle
A18: nailgun | B18: shot | C18: count | F18: =_xlfn.TEXTJOIN("_","TRUE",$B18:$E18) -> shot_count | H18: 1 | J18: reload_delay
A19: nailgun | B19: clip | C19: size | F19: =_xlfn.TEXTJOIN("_","TRUE",$B19:$E19) -> clip_size | H19: 0 | J19: reload_delay_first
A20: nailgun | B20: reload | C20: delay | D20: first | F20: =_xlfn.TEXTJOIN("_","TRUE",$B20:$E20) -> reload_delay_first | H20: 0 | J20: reload_max_ammo
A21: nailgun | B21: reload | C21: delay | F21: =_xlfn.TEXTJOIN("_","TRUE",$B21:$E21) -> reload_delay | H21: 0 | J21: sfx_fire
A22: perforator | B22: fn | C22: fire | F22: =_xlfn.TEXTJOIN("_","TRUE",$B22:$E22) -> fn_fire | H22: perforator nail | J22: shot_count
A23: perforator | B23: fn | C23: spread | F23: =_xlfn.TEXTJOIN("_","TRUE",$B23:$E23) -> fn_spread | H23: oval | J23: splash_dmg
A24: perforator | B24: ammo | C24: type | F24: =_xlfn.TEXTJOIN("_","TRUE",$B24:$E24) -> ammo_type | H24: nails | J24: spread
A25: perforator | B25: ammo | C25: cost | F25: =_xlfn.TEXTJOIN("_","TRUE",$B25:$E25) -> ammo_cost | H25: 2 | J25: timer
A26: perforator | B26: attack | C26: delay | F26: =_xlfn.TEXTJOIN("_","TRUE",$B26:$E26) -> attack_delay | H26: 0.09 | J26: vel
A27: perforator | B27: dmg | F27: =_xlfn.TEXTJOIN("_","TRUE",$B27:$E27) -> dmg | H27: 9
A28: perforator | B28: splash | C28: dmg | F28: =_xlfn.TEXTJOIN("_","TRUE",$B28:$E28) -> splash_dmg | H28: 0
A29: perforator | B29: spread | F29: =_xlfn.TEXTJOIN("_","TRUE",$B29:$E29) -> spread | H29: '7.5 7.5 0'
A30: perforator | B30: sfx | C30: fire | F30: =_xlfn.TEXTJOIN("_","TRUE",$B30:$E30) -> sfx_fire | H30: weapons/spike2.wav
A31: perforator | B31: vel | F31: =_xlfn.TEXTJOIN("_","TRUE",$B31:$E31) -> vel | H31: 980 0 0'
A32: perforator | B32: fn | C32: origin | F32: =_xlfn.TEXTJOIN("_","TRUE",$B32:$E32) -> fn_origin | H32: circle
A33: perforator | B33: origin | C33: base | D33: offset | F33: =_xlfn.TEXTJOIN("_","TRUE",$B33:$E33) -> origin_base_offset | H33: '0 11 16'
A34: perforator | B34: origin | C34: angle | D34: change | F34: =_xlfn.TEXTJOIN("_","TRUE",$B34:$E34) -> origin_angle_change | H34: 135
A35: perforator | B35: origin | C35: angle | D35: offset | F35: =_xlfn.TEXTJOIN("_","TRUE",$B35:$E35) -> origin_angle_offset | H35: 45
A36: perforator | B36: origin | C36: circle | D36: radius | F36: =_xlfn.TEXTJOIN("_","TRUE",$B36:$E36) -> origin_circle_radius | H36: 1.25
A37: perforator | B37: shot | C37: count | F37: =_xlfn.TEXTJOIN("_","TRUE",$B37:$E37) -> shot_count | H37: 2
A38: perforator | B38: clip | C38: size | F38: =_xlfn.TEXTJOIN("_","TRUE",$B38:$E38) -> clip_size | H38: 0
A39: perforator | B39: reload | C39: delay | D39: first | F39: =_xlfn.TEXTJOIN("_","TRUE",$B39:$E39) -> reload_delay_first | H39: 0
A40: perforator | B40: reload | C40: delay | F40: =_xlfn.TEXTJOIN("_","TRUE",$B40:$E40) -> reload_delay | H40: 0
...

Sheet pair
B1: {=TRANSPOSE(_xlfn._xlws.FILTER(base!I:I,base!I:I<>""))} -> axe | C1: grenadelauncher | D1: lightninggun | E1: nailgun | F1: perforator | G1: rocketlauncher | H1: shotgun | I1: soldiershotgun | J1: supershotgun
A2: {=_xlfn._xlws.FILTER(base!J:J,base!J:J<>"")} -> ammo_cost | B2: =IF(AND(B1<>"",A2<>""),_xlfn.TEXTJOIN("_",TRUE,B$1,$A2),"") -> axe_ammo_cost | C2: =IF(AND(C1<>"",B2<>""),_xlfn.TEXTJOIN("_",TRUE,C$1,$A2),"") -> grenadelauncher_ammo_cost | D2: =IF(AND(D1<>"",C2<>""),_xlfn.TEXTJOIN("_",TRUE,D$1,$A2),"") -> lightninggun_ammo_cost | E2: =IF(AND(E1<>"",D2<>""),_xlfn.TEXTJOIN("_",TRUE,E$1,$A2),"") -> nailgun_ammo_cost | F2: =IF(AND(F1<>"",E2<>""),_xlfn.TEXTJOIN("_",TRUE,F$1,$A2),"") -> perforator_ammo_cost | G2: =IF(AND(G1<>"",F2<>""),_xlfn.TEXTJOIN("_",TRUE,G$1,$A2),"") -> rocketlauncher_ammo_cost | H2: =IF(AND(H1<>"",G2<>""),_xlfn.TEXTJOIN("_",TRUE,H$1,$A2),"") -> shotgun_ammo_cost | I2: =IF(AND(I1<>"",H2<>""),_xlfn.TEXTJOIN("_",TRUE,I$1,$A2),"") -> soldiershotgun_ammo_cost | ... Z2: =IF(AND(Z1<>"",Y2<>""),_xlfn.TEXTJOIN("_",TRUE,Z$1,$A2),"") | AA2: =IF(AND($B1<>"",AA$1<>""),_xlfn.TEXTJOIN("_",TRUE,$B1,AA$1),"") | AB2: =IF(AND($B1<>"",AB$1<>""),_xlfn.TEXTJOIN("_",TRUE,$B1,AB$1),"") | AC2: =IF(AND($B1<>"",AC$1<>""),_xlfn.TEXTJOIN("_",TRUE,$B1,AC$1),"") | AD2: =IF(AND($B1<>"",AD$1<>""),_xlfn.TEXTJOIN("_",TRUE,$B1,AD$1),"") | AE2: =IF(AND($B1<>"",AE$1<>""),_xlfn.TEXTJOIN("_",TRUE,$B1,AE$1),"") | AF2: =IF(AND($B1<>"",AF$1<>""),_xlfn.TEXTJOIN("_",TRUE,$B1,AF$1),"") | AG2: =IF(AND($B1<>"",AG$1<>""),_xlfn.TEXTJOIN("_",TRUE,$B1,AG$1),"") | AH2: =IF(AND($B1<>"",AH$1<>""),_xlfn.TEXTJOIN("_",TRUE,$B1,AH$1),"") | ... AT2: =IF(AND($B1<>"",AT$1<>""),_xlfn.TEXTJOIN("_",TRUE,$B1,AT$1),"")
A3: ammo_type | B3: =IF(AND(B2<>"",A3<>""),_xlfn.TEXTJOIN("_",TRUE,B$1,$A3),"") -> axe_ammo_type | C3: =IF(AND(C2<>"",B3<>""),_xlfn.TEXTJOIN("_",TRUE,C$1,$A3),"") -> grenadelauncher_ammo_type | D3: =IF(AND(D2<>"",C3<>""),_xlfn.TEXTJOIN("_",TRUE,D$1,$A3),"") -> lightninggun_ammo_type | E3: =IF(AND(E2<>"",D3<>""),_xlfn.TEXTJOIN("_",TRUE,E$1,$A3),"") -> nailgun_ammo_type | F3: =IF(AND(F2<>"",E3<>""),_xlfn.TEXTJOIN("_",TRUE,F$1,$A3),"") -> perforator_ammo_type | G3: =IF(AND(G2<>"",F3<>""),_xlfn.TEXTJOIN("_",TRUE,G$1,$A3),"") -> rocketlauncher_ammo_type | H3: =IF(AND(H2<>"",G3<>""),_xlfn.TEXTJOIN("_",TRUE,H$1,$A3),"") -> shotgun_ammo_type | I3: =IF(AND(I2<>"",H3<>""),_xlfn.TEXTJOIN("_",TRUE,I$1,$A3),"") -> soldiershotgun_ammo_type | ... Z3: =IF(AND(Z2<>"",Y3<>""),_xlfn.TEXTJOIN("_",TRUE,Z$1,$A3),"") | AA3: =IF(AND($A3<>"",AA$1<>""),_xlfn.TEXTJOIN("_",TRUE,$A3,AA$1),"") | AB3: =IF(AND($A3<>"",AB$1<>""),_xlfn.TEXTJOIN("_",TRUE,$A3,AB$1),"") | AC3: =IF(AND($A3<>"",AC$1<>""),_xlfn.TEXTJOIN("_",TRUE,$A3,AC$1),"") | AD3: =IF(AND($A3<>"",AD$1<>""),_xlfn.TEXTJOIN("_",TRUE,$A3,AD$1),"") | AE3: =IF(AND($A3<>"",AE$1<>""),_xlfn.TEXTJOIN("_",TRUE,$A3,AE$1),"") | AF3: =IF(AND($A3<>"",AF$1<>""),_xlfn.TEXTJOIN("_",TRUE,$A3,AF$1),"") | AG3: =IF(AND($A3<>"",AG$1<>""),_xlfn.TEXTJOIN("_",TRUE,$A3,AG$1),"") | AH3: =IF(AND($A3<>"",AH$1<>""),_xlfn.TEXTJOIN("_",TRUE,$A3,AH$1),"") | ... AT3: =IF(AND($A3<>"",AT$1<>""),_xlfn.TEXTJOIN("_",TRUE,$A3,AT$1),"")
A4: attack_delay | B4: =IF(AND(B3<>"",A4<>""),_xlfn.TEXTJOIN("_",TRUE,B$1,$A4),"") -> axe_attack_delay | C4: =IF(AND(C3<>"",B4<>""),_xlfn.TEXTJOIN("_",TRUE,C$1,$A4),"") -> grenadelauncher_attack_delay | D4: =IF(AND(D3<>"",C4<>""),_xlfn.TEXTJOIN("_",TRUE,D$1,$A4),"") -> lightninggun_attack_delay | E4: =IF(AND(E3<>"",D4<>""),_xlfn.TEXTJOIN("_",TRUE,E$1,$A4),"") -> nailgun_attack_delay | F4: =IF(AND(F3<>"",E4<>""),_xlfn.TEXTJOIN("_",TRUE,F$1,$A4),"") -> perforator_attack_delay | G4: =IF(AND(G3<>"",F4<>""),_xlfn.TEXTJOIN("_",TRUE,G$1,$A4),"") -> rocketlauncher_attack_delay | H4: =IF(AND(H3<>"",G4<>""),_xlfn.TEXTJOIN("_",TRUE,H$1,$A4),"") -> shotgun_attack_delay | I4: =IF(AND(I3<>"",H4<>""),_xlfn.TEXTJOIN("_",TRUE,I$1,$A4),"") -> soldiershotgun_attack_delay | ... Z4: =IF(AND(Z3<>"",Y4<>""),_xlfn.TEXTJOIN("_",TRUE,Z$1,$A4),"")
A5: bounce | B5: =IF(AND(B4<>"",A5<>""),_xlfn.TEXTJOIN("_",TRUE,B$1,$A5),"") -> axe_bounce | C5: =IF(AND(C4<>"",B5<>""),_xlfn.TEXTJOIN("_",TRUE,C$1,$A5),"") -> grenadelauncher_bounce | D5: =IF(AND(D4<>"",C5<>""),_xlfn.TEXTJOIN("_",TRUE,D$1,$A5),"") -> lightninggun_bounce | E5: =IF(AND(E4<>"",D5<>""),_xlfn.TEXTJOIN("_",TRUE,E$1,$A5),"") -> nailgun_bounce | F5: =IF(AND(F4<>"",E5<>""),_xlfn.TEXTJOIN("_",TRUE,F$1,$A5),"") -> perforator_bounce | G5: =IF(AND(G4<>"",F5<>""),_xlfn.TEXTJOIN("_",TRUE,G$1,$A5),"") -> rocketlauncher_bounce | H5: =IF(AND(H4<>"",G5<>""),_xlfn.TEXTJOIN("_",TRUE,H$1,$A5),"") -> shotgun_bounce | I5: =IF(AND(I4<>"",H5<>""),_xlfn.TEXTJOIN("_",TRUE,I$1,$A5),"") -> soldiershotgun_bounce | ... Z5: =IF(AND(Z4<>"",Y5<>""),_xlfn.TEXTJOIN("_",TRUE,Z$1,$A5),"") | AA5: =IF(AND($A5<>"",AA$1<>""),_xlfn.TEXTJOIN("_",TRUE,$A5,AA$1),"") | AB5: =IF(AND($A5<>"",AB$1<>""),_xlfn.TEXTJOIN("_",TRUE,$A5,AB$1),"") | AC5: =IF(AND($A5<>"",AC$1<>""),_xlfn.TEXTJOIN("_",TRUE,$A5,AC$1),"") | AD5: =IF(AND($A5<>"",AD$1<>""),_xlfn.TEXTJOIN("_",TRUE,$A5,AD$1),"") | AE5: =IF(AND($A5<>"",AE$1<>""),_xlfn.TEXTJOIN("_",TRUE,$A5,AE$1),"") | AF5: =IF(AND($A5<>"",AF$1<>""),_xlfn.TEXTJOIN("_",TRUE,$A5,AF$1),"") | AG5: =IF(AND($A5<>"",AG$1<>""),_xlfn.TEXTJOIN("_",TRUE,$A5,AG$1),"") | AH5: =IF(AND($A5<>"",AH$1<>""),_xlfn.TEXTJOIN("_",TRUE,$A5,AH$1),"") | ... AT5: =IF(AND($A5<>"",AT$1<>""),_xlfn.TEXTJOIN("_",TRUE,$A5,AT$1),"")
A6: clip_size | B6: =IF(AND(B5<>"",A6<>""),_xlfn.TEXTJOIN("_",TRUE,B$1,$A6),"") -> axe_clip_size | C6: =IF(AND(C5<>"",B6<>""),_xlfn.TEXTJOIN("_",TRUE,C$1,$A6),"") -> grenadelauncher_clip_size | D6: =IF(AND(D5<>"",C6<>""),_xlfn.TEXTJOIN("_",TRUE,D$1,$A6),"") -> lightninggun_clip_size | E6: =IF(AND(E5<>"",D6<>""),_xlfn.TEXTJOIN("_",TRUE,E$1,$A6),"") -> nailgun_clip_size | F6: =IF(AND(F5<>"",E6<>""),_xlfn.TEXTJOIN("_",TRUE,F$1,$A6),"") -> perforator_clip_size | G6: =IF(AND(G5<>"",F6<>""),_xlfn.TEXTJOIN("_",TRUE,G$1,$A6),"") -> rocketlauncher_clip_size | H6: =IF(AND(H5<>"",G6<>""),_xlfn.TEXTJOIN("_",TRUE,H$1,$A6),"") -> shotgun_clip_size | I6: =IF(AND(I5<>"",H6<>""),_xlfn.TEXTJOIN("_",TRUE,I$1,$A6),"") -> soldiershotgun_clip_size | ... Z6: =IF(AND(Z5<>"",Y6<>""),_xlfn.TEXTJOIN("_",TRUE,Z$1,$A6),"") | AA6: =IF(AND($A6<>"",AA$1<>""),_xlfn.TEXTJOIN("_",TRUE,$A6,AA$1),"") | AB6: =IF(AND($A6<>"",AB$1<>""),_xlfn.TEXTJOIN("_",TRUE,$A6,AB$1),"") | AC6: =IF(AND($A6<>"",AC$1<>""),_xlfn.TEXTJOIN("_",TRUE,$A6,AC$1),"") | AD6: =IF(AND($A6<>"",AD$1<>""),_xlfn.TEXTJOIN("_",TRUE,$A6,AD$1),"") | AE6: =IF(AND($A6<>"",AE$1<>""),_xlfn.TEXTJOIN("_",TRUE,$A6,AE$1),"") | AF6: =IF(AND($A6<>"",AF$1<>""),_xlfn.TEXTJOIN("_",TRUE,$A6,AF$1),"") | AG6: =IF(AND($A6<>"",AG$1<>""),_xlfn.TEXTJOIN("_",TRUE,$A6,AG$1),"") | AH6: =IF(AND($A6<>"",AH$1<>""),_xlfn.TEXTJOIN("_",TRUE,$A6,AH$1),"") | ... AT6: =IF(AND($A6<>"",AT$1<>""),_xlfn.TEXTJOIN("_",TRUE,$A6,AT$1),"")
A7: dmg | B7: =IF(AND(B6<>"",A7<>""),_xlfn.TEXTJOIN("_",TRUE,B$1,$A7),"") -> axe_dmg | C7: =IF(AND(C6<>"",B7<>""),_xlfn.TEXTJOIN("_",TRUE,C$1,$A7),"") -> grenadelauncher_dmg | D7: =IF(AND(D6<>"",C7<>""),_xlfn.TEXTJOIN("_",TRUE,D$1,$A7),"") -> lightninggun_dmg | E7: =IF(AND(E6<>"",D7<>""),_xlfn.TEXTJOIN("_",TRUE,E$1,$A7),"") -> nailgun_dmg | F7: =IF(AND(F6<>"",E7<>""),_xlfn.TEXTJOIN("_",TRUE,F$1,$A7),"") -> perforator_dmg | G7: =IF(AND(G6<>"",F7<>""),_xlfn.TEXTJOIN("_",TRUE,G$1,$A7),"") -> rocketlauncher_dmg | H7: =IF(AND(H6<>"",G7<>""),_xlfn.TEXTJOIN("_",TRUE,H$1,$A7),"") -> shotgun_dmg | I7: =IF(AND(I6<>"",H7<>""),_xlfn.TEXTJOIN("_",TRUE,I$1,$A7),"") -> soldiershotgun_dmg | ... Z7: =IF(AND(Z6<>"",Y7<>""),_xlfn.TEXTJOIN("_",TRUE,Z$1,$A7),"") | AA7: =IF(AND($A7<>"",AA$1<>""),_xlfn.TEXTJOIN("_",TRUE,$A7,AA$1),"") | AB7: =IF(AND($A7<>"",AB$1<>""),_xlfn.TEXTJOIN("_",TRUE,$A7,AB$1),"") | AC7: =IF(AND($A7<>"",AC$1<>""),_xlfn.TEXTJOIN("_",TRUE,$A7,AC$1),"") | AD7: =IF(AND($A7<>"",AD$1<>""),_xlfn.TEXTJOIN("_",TRUE,$A7,AD$1),"") | AE7: =IF(AND($A7<>"",AE$1<>""),_xlfn.TEXTJOIN("_",TRUE,$A7,AE$1),"") | AF7: =IF(AND($A7<>"",AF$1<>""),_xlfn.TEXTJOIN("_",TRUE,$A7,AF$1),"") | AG7: =IF(AND($A7<>"",AG$1<>""),_xlfn.TEXTJOIN("_",TRUE,$A7,AG$1),"") | AH7: =IF(AND($A7<>"",AH$1<>""),_xlfn.TEXTJOIN("_",TRUE,$A7,AH$1),"") | ... AT7: =IF(AND($A7<>"",AT$1<>""),_xlfn.TEXTJOIN("_",TRUE,$A7,AT$1),"")
A8: dmg_splash | B8: =IF(AND(B7<>"",A8<>""),_xlfn.TEXTJOIN("_",TRUE,B$1,$A8),"") -> axe_dmg_splash | C8: =IF(AND(C7<>"",B8<>""),_xlfn.TEXTJOIN("_",TRUE,C$1,$A8),"") -> grenadelauncher_dmg_splash | D8: =IF(AND(D7<>"",C8<>""),_xlfn.TEXTJOIN("_",TRUE,D$1,$A8),"") -> lightninggun_dmg_splash | E8: =IF(AND(E7<>"",D8<>""),_xlfn.TEXTJOIN("_",TRUE,E$1,$A8),"") -> nailgun_dmg_splash | F8: =IF(AND(F7<>"",E8<>""),_xlfn.TEXTJOIN("_",TRUE,F$1,$A8),"") -> perforator_dmg_splash | G8: =IF(AND(G7<>"",F8<>""),_xlfn.TEXTJOIN("_",TRUE,G$1,$A8),"") -> rocketlauncher_dmg_splash | H8: =IF(AND(H7<>"",G8<>""),_xlfn.TEXTJOIN("_",TRUE,H$1,$A8),"") -> shotgun_dmg_splash | I8: =IF(AND(I7<>"",H8<>""),_xlfn.TEXTJOIN("_",TRUE,I$1,$A8),"") -> soldiershotgun_dmg_splash | ... Z8: =IF(AND(Z7<>"",Y8<>""),_xlfn.TEXTJOIN("_",TRUE,Z$1,$A8),"") | AA8: =IF(AND($A8<>"",AA$1<>""),_xlfn.TEXTJOIN("_",TRUE,$A8,AA$1),"") | AB8: =IF(AND($A8<>"",AB$1<>""),_xlfn.TEXTJOIN("_",TRUE,$A8,AB$1),"") | AC8: =IF(AND($A8<>"",AC$1<>""),_xlfn.TEXTJOIN("_",TRUE,$A8,AC$1),"") | AD8: =IF(AND($A8<>"",AD$1<>""),_xlfn.TEXTJOIN("_",TRUE,$A8,AD$1),"") | AE8: =IF(AND($A8<>"",AE$1<>""),_xlfn.TEXTJOIN("_",TRUE,$A8,AE$1),"") | AF8: =IF(AND($A8<>"",AF$1<>""),_xlfn.TEXTJOIN("_",TRUE,$A8,AF$1),"") | AG8: =IF(AND($A8<>"",AG$1<>""),_xlfn.TEXTJOIN("_",TRUE,$A8,AG$1),"") | AH8: =IF(AND($A8<>"",AH$1<>""),_xlfn.TEXTJOIN("_",TRUE,$A8,AH$1),"") | ... AT8: =IF(AND($A8<>"",AT$1<>""),_xlfn.TEXTJOIN("_",TRUE,$A8,AT$1),"")
A9: fn_fire | B9: =IF(AND(B8<>"",A9<>""),_xlfn.TEXTJOIN("_",TRUE,B$1,$A9),"") -> axe_fn_fire | C9: =IF(AND(C8<>"",B9<>""),_xlfn.TEXTJOIN("_",TRUE,C$1,$A9),"") -> grenadelauncher_fn_fire | D9: =IF(AND(D8<>"",C9<>""),_xlfn.TEXTJOIN("_",TRUE,D$1,$A9),"") -> lightninggun_fn_fire | E9: =IF(AND(E8<>"",D9<>""),_xlfn.TEXTJOIN("_",TRUE,E$1,$A9),"") -> nailgun_fn_fire | F9: =IF(AND(F8<>"",E9<>""),_xlfn.TEXTJOIN("_",TRUE,F$1,$A9),"") -> perforator_fn_fire | G9: =IF(AND(G8<>"",F9<>""),_xlfn.TEXTJOIN("_",TRUE,G$1,$A9),"") -> rocketlauncher_fn_fire | H9: =IF(AND(H8<>"",G9<>""),_xlfn.TEXTJOIN("_",TRUE,H$1,$A9),"") -> shotgun_fn_fire | I9: =IF(AND(I8<>"",H9<>""),_xlfn.TEXTJOIN("_",TRUE,I$1,$A9),"") -> soldiershotgun_fn_fire | ... Z9: =IF(AND(Z8<>"",Y9<>""),_xlfn.TEXTJOIN("_",TRUE,Z$1,$A9),"") | AA9: =IF(AND($A9<>"",AA$1<>""),_xlfn.TEXTJOIN("_",TRUE,$A9,AA$1),"") | AB9: =IF(AND($A9<>"",AB$1<>""),_xlfn.TEXTJOIN("_",TRUE,$A9,AB$1),"") | AC9: =IF(AND($A9<>"",AC$1<>""),_xlfn.TEXTJOIN("_",TRUE,$A9,AC$1),"") | AD9: =IF(AND($A9<>"",AD$1<>""),_xlfn.TEXTJOIN("_",TRUE,$A9,AD$1),"") | AE9: =IF(AND($A9<>"",AE$1<>""),_xlfn.TEXTJOIN("_",TRUE,$A9,AE$1),"") | AF9: =IF(AND($A9<>"",AF$1<>""),_xlfn.TEXTJOIN("_",TRUE,$A9,AF$1),"") | AG9: =IF(AND($A9<>"",AG$1<>""),_xlfn.TEXTJOIN("_",TRUE,$A9,AG$1),"") | AH9: =IF(AND($A9<>"",AH$1<>""),_xlfn.TEXTJOIN("_",TRUE,$A9,AH$1),"") | ... AT9: =IF(AND($A9<>"",AT$1<>""),_xlfn.TEXTJOIN("_",TRUE,$A9,AT$1),"")
A10: fn_origin | B10: =IF(AND(B9<>"",A10<>""),_xlfn.TEXTJOIN("_",TRUE,B$1,$A10),"") -> axe_fn_origin | C10: =IF(AND(C9<>"",B10<>""),_xlfn.TEXTJOIN("_",TRUE,C$1,$A10),"") -> grenadelauncher_fn_origin | D10: =IF(AND(D9<>"",C10<>""),_xlfn.TEXTJOIN("_",TRUE,D$1,$A10),"") -> lightninggun_fn_origin | E10: =IF(AND(E9<>"",D10<>""),_xlfn.TEXTJOIN("_",TRUE,E$1,$A10),"") -> nailgun_fn_origin | F10: =IF(AND(F9<>"",E10<>""),_xlfn.TEXTJOIN("_",TRUE,F$1,$A10),"") -> perforator_fn_origin | G10: =IF(AND(G9<>"",F10<>""),_xlfn.TEXTJOIN("_",TRUE,G$1,$A10),"") -> rocketlauncher_fn_origin | H10: =IF(AND(H9<>"",G10<>""),_xlfn.TEXTJOIN("_",TRUE,H$1,$A10),"") -> shotgun_fn_origin | I10: =IF(AND(I9<>"",H10<>""),_xlfn.TEXTJOIN("_",TRUE,I$1,$A10),"") -> soldiershotgun_fn_origin | ... Z10: =IF(AND(Z9<>"",Y10<>""),_xlfn.TEXTJOIN("_",TRUE,Z$1,$A10),"") | AA10: =IF(AND($A10<>"",AA$1<>""),_xlfn.TEXTJOIN("_",TRUE,$A10,AA$1),"") | AB10: =IF(AND($A10<>"",AB$1<>""),_xlfn.TEXTJOIN("_",TRUE,$A10,AB$1),"") | AC10: =IF(AND($A10<>"",AC$1<>""),_xlfn.TEXTJOIN("_",TRUE,$A10,AC$1),"") | AD10: =IF(AND($A10<>"",AD$1<>""),_xlfn.TEXTJOIN("_",TRUE,$A10,AD$1),"") | AE10: =IF(AND($A10<>"",AE$1<>""),_xlfn.TEXTJOIN("_",TRUE,$A10,AE$1),"") | AF10: =IF(AND($A10<>"",AF$1<>""),_xlfn.TEXTJOIN("_",TRUE,$A10,AF$1),"") | AG10: =IF(AND($A10<>"",AG$1<>""),_xlfn.TEXTJOIN("_",TRUE,$A10,AG$1),"") | AH10: =IF(AND($A10<>"",AH$1<>""),_xlfn.TEXTJOIN("_",TRUE,$A10,AH$1),"") | ... AT10: =IF(AND($A10<>"",AT$1<>""),_xlfn.TEXTJOIN("_",TRUE,$A10,AT$1),"")
A11: fn_spread | B11: =IF(AND(B10<>"",A11<>""),_xlfn.TEXTJOIN("_",TRUE,B$1,$A11),"") -> axe_fn_spread | C11: =IF(AND(C10<>"",B11<>""),_xlfn.TEXTJOIN("_",TRUE,C$1,$A11),"") -> grenadelauncher_fn_spread | D11: =IF(AND(D10<>"",C11<>""),_xlfn.TEXTJOIN("_",TRUE,D$1,$A11),"") -> lightninggun_fn_spread | E11: =IF(AND(E10<>"",D11<>""),_xlfn.TEXTJOIN("_",TRUE,E$1,$A11),"") -> nailgun_fn_spread | F11: =IF(AND(F10<>"",E11<>""),_xlfn.TEXTJOIN("_",TRUE,F$1,$A11),"") -> perforator_fn_spread | G11: =IF(AND(G10<>"",F11<>""),_xlfn.TEXTJOIN("_",TRUE,G$1,$A11),"") -> rocketlauncher_fn_spread | H11: =IF(AND(H10<>"",G11<>""),_xlfn.TEXTJOIN("_",TRUE,H$1,$A11),"") -> shotgun_fn_spread | I11: =IF(AND(I10<>"",H11<>""),_xlfn.TEXTJOIN("_",TRUE,I$1,$A11),"") -> soldiershotgun_fn_spread | ... Z11: =IF(AND(Z10<>"",Y11<>""),_xlfn.TEXTJOIN("_",TRUE,Z$1,$A11),"") | AA11: =IF(AND($A11<>"",AA$1<>""),_xlfn.TEXTJOIN("_",TRUE,$A11,AA$1),"") | AB11: =IF(AND($A11<>"",AB$1<>""),_xlfn.TEXTJOIN("_",TRUE,$A11,AB$1),"") | AC11: =IF(AND($A11<>"",AC$1<>""),_xlfn.TEXTJOIN("_",TRUE,$A11,AC$1),"") | AD11: =IF(AND($A11<>"",AD$1<>""),_xlfn.TEXTJOIN("_",TRUE,$A11,AD$1),"") | AE11: =IF(AND($A11<>"",AE$1<>""),_xlfn.TEXTJOIN("_",TRUE,$A11,AE$1),"") | AF11: =IF(AND($A11<>"",AF$1<>""),_xlfn.TEXTJOIN("_",TRUE,$A11,AF$1),"") | AG11: =IF(AND($A11<>"",AG$1<>""),_xlfn.TEXTJOIN("_",TRUE,$A11,AG$1),"") | AH11: =IF(AND($A11<>"",AH$1<>""),_xlfn.TEXTJOIN("_",TRUE,$A11,AH$1),"") | ... AT11: =IF(AND($A11<>"",AT$1<>""),_xlfn.TEXTJOIN("_",TRUE,$A11,AT$1),"")
A12: impart_vel | B12: =IF(AND(B11<>"",A12<>""),_xlfn.TEXTJOIN("_",TRUE,B$1,$A12),"") -> axe_impart_vel | C12: =IF(AND(C11<>"",B12<>""),_xlfn.TEXTJOIN("_",TRUE,C$1,$A12),"") -> grenadelauncher_impart_vel | D12: =IF(AND(D11<>"",C12<>""),_xlfn.TEXTJOIN("_",TRUE,D$1,$A12),"") -> lightninggun_impart_vel | E12: =IF(AND(E11<>"",D12<>""),_xlfn.TEXTJOIN("_",TRUE,E$1,$A12),"") -> nailgun_impart_vel | F12: =IF(AND(F11<>"",E12<>""),_xlfn.TEXTJOIN("_",TRUE,F$1,$A12),"") -> perforator_impart_vel | G12: =IF(AND(G11<>"",F12<>""),_xlfn.TEXTJOIN("_",TRUE,G$1,$A12),"") -> rocketlauncher_impart_vel | H12: =IF(AND(H11<>"",G12<>""),_xlfn.TEXTJOIN("_",TRUE,H$1,$A12),"") -> shotgun_impart_vel | I12: =IF(AND(I11<>"",H12<>""),_xlfn.TEXTJOIN("_",TRUE,I$1,$A12),"") -> soldiershotgun_impart_vel | ... Z12: =IF(AND(Z11<>"",Y12<>""),_xlfn.TEXTJOIN("_",TRUE,Z$1,$A12),"") | AA12: =IF(AND($A12<>"",AA$1<>""),_xlfn.TEXTJOIN("_",TRUE,$A12,AA$1),"") | AB12: =IF(AND($A12<>"",AB$1<>""),_xlfn.TEXTJOIN("_",TRUE,$A12,AB$1),"") | AC12: =IF(AND($A12<>"",AC$1<>""),_xlfn.TEXTJOIN("_",TRUE,$A12,AC$1),"") | AD12: =IF(AND($A12<>"",AD$1<>""),_xlfn.TEXTJOIN("_",TRUE,$A12,AD$1),"") | AE12: =IF(AND($A12<>"",AE$1<>""),_xlfn.TEXTJOIN("_",TRUE,$A12,AE$1),"") | AF12: =IF(AND($A12<>"",AF$1<>""),_xlfn.TEXTJOIN("_",TRUE,$A12,AF$1),"") | AG12: =IF(AND($A12<>"",AG$1<>""),_xlfn.TEXTJOIN("_",TRUE,$A12,AG$1),"") | AH12: =IF(AND($A12<>"",AH$1<>""),_xlfn.TEXTJOIN("_",TRUE,$A12,AH$1),"") | ... AT12: =IF(AND($A12<>"",AT$1<>""),_xlfn.TEXTJOIN("_",TRUE,$A12,AT$1),"")
A13: origin_angle_change | B13: =IF(AND(B12<>"",A13<>""),_xlfn.TEXTJOIN("_",TRUE,B$1,$A13),"") -> axe_origin_angle_change | C13: =IF(AND(C12<>"",B13<>""),_xlfn.TEXTJOIN("_",TRUE,C$1,$A13),"") -> grenadelauncher_origin_angle_change | D13: =IF(AND(D12<>"",C13<>""),_xlfn.TEXTJOIN("_",TRUE,D$1,$A13),"") -> lightninggun_origin_angle_change | E13: =IF(AND(E12<>"",D13<>""),_xlfn.TEXTJOIN("_",TRUE,E$1,$A13),"") -> nailgun_origin_angle_change | F13: =IF(AND(F12<>"",E13<>""),_xlfn.TEXTJOIN("_",TRUE,F$1,$A13),"") -> perforator_origin_angle_change | G13: =IF(AND(G12<>"",F13<>""),_xlfn.TEXTJOIN("_",TRUE,G$1,$A13),"") -> rocketlauncher_origin_angle_change | H13: =IF(AND(H12<>"",G13<>""),_xlfn.TEXTJOIN("_",TRUE,H$1,$A13),"") -> shotgun_origin_angle_change | I13: =IF(AND(I12<>"",H13<>""),_xlfn.TEXTJOIN("_",TRUE,I$1,$A13),"") -> soldiershotgun_origin_angle_change | ... Z13: =IF(AND(Z12<>"",Y13<>""),_xlfn.TEXTJOIN("_",TRUE,Z$1,$A13),"") | AA13: =IF(AND($A13<>"",AA$1<>""),_xlfn.TEXTJOIN("_",TRUE,$A13,AA$1),"") | AB13: =IF(AND($A13<>"",AB$1<>""),_xlfn.TEXTJOIN("_",TRUE,$A13,AB$1),"") | AC13: =IF(AND($A13<>"",AC$1<>""),_xlfn.TEXTJOIN("_",TRUE,$A13,AC$1),"") | AD13: =IF(AND($A13<>"",AD$1<>""),_xlfn.TEXTJOIN("_",TRUE,$A13,AD$1),"") | AE13: =IF(AND($A13<>"",AE$1<>""),_xlfn.TEXTJOIN("_",TRUE,$A13,AE$1),"") | AF13: =IF(AND($A13<>"",AF$1<>""),_xlfn.TEXTJOIN("_",TRUE,$A13,AF$1),"") | AG13: =IF(AND($A13<>"",AG$1<>""),_xlfn.TEXTJOIN("_",TRUE,$A13,AG$1),"") | AH13: =IF(AND($A13<>"",AH$1<>""),_xlfn.TEXTJOIN("_",TRUE,$A13,AH$1),"") | ... AT13: =IF(AND($A13<>"",AT$1<>""),_xlfn.TEXTJOIN("_",TRUE,$A13,AT$1),"")
A14: origin_angle_offset | B14: =IF(AND(B13<>"",A14<>""),_xlfn.TEXTJOIN("_",TRUE,B$1,$A14),"") -> axe_origin_angle_offset | C14: =IF(AND(C13<>"",B14<>""),_xlfn.TEXTJOIN("_",TRUE,C$1,$A14),"") -> grenadelauncher_origin_angle_offset | D14: =IF(AND(D13<>"",C14<>""),_xlfn.TEXTJOIN("_",TRUE,D$1,$A14),"") -> lightninggun_origin_angle_offset | E14: =IF(AND(E13<>"",D14<>""),_xlfn.TEXTJOIN("_",TRUE,E$1,$A14),"") -> nailgun_origin_angle_offset | F14: =IF(AND(F13<>"",E14<>""),_xlfn.TEXTJOIN("_",TRUE,F$1,$A14),"") -> perforator_origin_angle_offset | G14: =IF(AND(G13<>"",F14<>""),_xlfn.TEXTJOIN("_",TRUE,G$1,$A14),"") -> rocketlauncher_origin_angle_offset | H14: =IF(AND(H13<>"",G14<>""),_xlfn.TEXTJOIN("_",TRUE,H$1,$A14),"") -> shotgun_origin_angle_offset | I14: =IF(AND(I13<>"",H14<>""),_xlfn.TEXTJOIN("_",TRUE,I$1,$A14),"") -> soldiershotgun_origin_angle_offset | ... Z14: =IF(AND(Z13<>"",Y14<>""),_xlfn.TEXTJOIN("_",TRUE,Z$1,$A14),"") | AA14: =IF(AND($A14<>"",AA$1<>""),_xlfn.TEXTJOIN("_",TRUE,$A14,AA$1),"") | AB14: =IF(AND($A14<>"",AB$1<>""),_xlfn.TEXTJOIN("_",TRUE,$A14,AB$1),"") | AC14: =IF(AND($A14<>"",AC$1<>""),_xlfn.TEXTJOIN("_",TRUE,$A14,AC$1),"") | AD14: =IF(AND($A14<>"",AD$1<>""),_xlfn.TEXTJOIN("_",TRUE,$A14,AD$1),"") | AE14: =IF(AND($A14<>"",AE$1<>""),_xlfn.TEXTJOIN("_",TRUE,$A14,AE$1),"") | AF14: =IF(AND($A14<>"",AF$1<>""),_xlfn.TEXTJOIN("_",TRUE,$A14,AF$1),"") | AG14: =IF(AND($A14<>"",AG$1<>""),_xlfn.TEXTJOIN("_",TRUE,$A14,AG$1),"") | AH14: =IF(AND($A14<>"",AH$1<>""),_xlfn.TEXTJOIN("_",TRUE,$A14,AH$1),"") | ... AT14: =IF(AND($A14<>"",AT$1<>""),_xlfn.TEXTJOIN("_",TRUE,$A14,AT$1),"")
A15: origin_base_offset | B15: =IF(AND(B14<>"",A15<>""),_xlfn.TEXTJOIN("_",TRUE,B$1,$A15),"") -> axe_origin_base_offset | C15: =IF(AND(C14<>"",B15<>""),_xlfn.TEXTJOIN("_",TRUE,C$1,$A15),"") -> grenadelauncher_origin_base_offset | D15: =IF(AND(D14<>"",C15<>""),_xlfn.TEXTJOIN("_",TRUE,D$1,$A15),"") -> lightninggun_origin_base_offset | E15: =IF(AND(E14<>"",D15<>""),_xlfn.TEXTJOIN("_",TRUE,E$1,$A15),"") -> nailgun_origin_base_offset | F15: =IF(AND(F14<>"",E15<>""),_xlfn.TEXTJOIN("_",TRUE,F$1,$A15),"") -> perforator_origin_base_offset | G15: =IF(AND(G14<>"",F15<>""),_xlfn.TEXTJOIN("_",TRUE,G$1,$A15),"") -> rocketlauncher_origin_base_offset | H15: =IF(AND(H14<>"",G15<>""),_xlfn.TEXTJOIN("_",TRUE,H$1,$A15),"") -> shotgun_origin_base_offset | I15: =IF(AND(I14<>"",H15<>""),_xlfn.TEXTJOIN("_",TRUE,I$1,$A15),"") -> soldiershotgun_origin_base_offset | ... Z15: =IF(AND(Z14<>"",Y15<>""),_xlfn.TEXTJOIN("_",TRUE,Z$1,$A15),"") | AA15: =IF(AND($A15<>"",AA$1<>""),_xlfn.TEXTJOIN("_",TRUE,$A15,AA$1),"") | AB15: =IF(AND($A15<>"",AB$1<>""),_xlfn.TEXTJOIN("_",TRUE,$A15,AB$1),"") | AC15: =IF(AND($A15<>"",AC$1<>""),_xlfn.TEXTJOIN("_",TRUE,$A15,AC$1),"") | AD15: =IF(AND($A15<>"",AD$1<>""),_xlfn.TEXTJOIN("_",TRUE,$A15,AD$1),"") | AE15: =IF(AND($A15<>"",AE$1<>""),_xlfn.TEXTJOIN("_",TRUE,$A15,AE$1),"") | AF15: =IF(AND($A15<>"",AF$1<>""),_xlfn.TEXTJOIN("_",TRUE,$A15,AF$1),"") | AG15: =IF(AND($A15<>"",AG$1<>""),_xlfn.TEXTJOIN("_",TRUE,$A15,AG$1),"") | AH15: =IF(AND($A15<>"",AH$1<>""),_xlfn.TEXTJOIN("_",TRUE,$A15,AH$1),"") | ... AT15: =IF(AND($A15<>"",AT$1<>""),_xlfn.TEXTJOIN("_",TRUE,$A15,AT$1),"")
A16: origin_circle_radius | B16: =IF(AND(B15<>"",A16<>""),_xlfn.TEXTJOIN("_",TRUE,B$1,$A16),"") -> axe_origin_circle_radius | C16: =IF(AND(C15<>"",B16<>""),_xlfn.TEXTJOIN("_",TRUE,C$1,$A16),"") -> grenadelauncher_origin_circle_radius | D16: =IF(AND(D15<>"",C16<>""),_xlfn.TEXTJOIN("_",TRUE,D$1,$A16),"") -> lightninggun_origin_circle_radius | E16: =IF(AND(E15<>"",D16<>""),_xlfn.TEXTJOIN("_",TRUE,E$1,$A16),"") -> nailgun_origin_circle_radius | F16: =IF(AND(F15<>"",E16<>""),_xlfn.TEXTJOIN("_",TRUE,F$1,$A16),"") -> perforator_origin_circle_radius | G16: =IF(AND(G15<>"",F16<>""),_xlfn.TEXTJOIN("_",TRUE,G$1,$A16),"") -> rocketlauncher_origin_circle_radius | H16: =IF(AND(H15<>"",G16<>""),_xlfn.TEXTJOIN("_",TRUE,H$1,$A16),"") -> shotgun_origin_circle_radius | I16: =IF(AND(I15<>"",H16<>""),_xlfn.TEXTJOIN("_",TRUE,I$1,$A16),"") -> soldiershotgun_origin_circle_radius | ... Z16: =IF(AND(Z15<>"",Y16<>""),_xlfn.TEXTJOIN("_",TRUE,Z$1,$A16),"")
A17: penetration_limit | B17: =IF(AND(B16<>"",A17<>""),_xlfn.TEXTJOIN("_",TRUE,B$1,$A17),"") -> axe_penetration_limit | C17: =IF(AND(C16<>"",B17<>""),_xlfn.TEXTJOIN("_",TRUE,C$1,$A17),"") -> grenadelauncher_penetration_limit | D17: =IF(AND(D16<>"",C17<>""),_xlfn.TEXTJOIN("_",TRUE,D$1,$A17),"") -> lightninggun_penetration_limit | E17: =IF(AND(E16<>"",D17<>""),_xlfn.TEXTJOIN("_",TRUE,E$1,$A17),"") -> nailgun_penetration_limit | F17: =IF(AND(F16<>"",E17<>""),_xlfn.TEXTJOIN("_",TRUE,F$1,$A17),"") -> perforator_penetration_limit | G17: =IF(AND(G16<>"",F17<>""),_xlfn.TEXTJOIN("_",TRUE,G$1,$A17),"") -> rocketlauncher_penetration_limit | H17: =IF(AND(H16<>"",G17<>""),_xlfn.TEXTJOIN("_",TRUE,H$1,$A17),"") -> shotgun_penetration_limit | I17: =IF(AND(I16<>"",H17<>""),_xlfn.TEXTJOIN("_",TRUE,I$1,$A17),"") -> soldiershotgun_penetration_limit | ... Z17: =IF(AND(Z16<>"",Y17<>""),_xlfn.TEXTJOIN("_",TRUE,Z$1,$A17),"")
A18: punch_angle | B18: =IF(AND(B17<>"",A18<>""),_xlfn.TEXTJOIN("_",TRUE,B$1,$A18),"") -> axe_punch_angle | C18: =IF(AND(C17<>"",B18<>""),_xlfn.TEXTJOIN("_",TRUE,C$1,$A18),"") -> grenadelauncher_punch_angle | D18: =IF(AND(D17<>"",C18<>""),_xlfn.TEXTJOIN("_",TRUE,D$1,$A18),"") -> lightninggun_punch_angle | E18: =IF(AND(E17<>"",D18<>""),_xlfn.TEXTJOIN("_",TRUE,E$1,$A18),"") -> nailgun_punch_angle | F18: =IF(AND(F17<>"",E18<>""),_xlfn.TEXTJOIN("_",TRUE,F$1,$A18),"") -> perforator_punch_angle | G18: =IF(AND(G17<>"",F18<>""),_xlfn.TEXTJOIN("_",TRUE,G$1,$A18),"") -> rocketlauncher_punch_angle | H18: =IF(AND(H17<>"",G18<>""),_xlfn.TEXTJOIN("_",TRUE,H$1,$A18),"") -> shotgun_punch_angle | I18: =IF(AND(I17<>"",H18<>""),_xlfn.TEXTJOIN("_",TRUE,I$1,$A18),"") -> soldiershotgun_punch_angle | ... Z18: =IF(AND(Z17<>"",Y18<>""),_xlfn.TEXTJOIN("_",TRUE,Z$1,$A18),"")
A19: reload_delay | B19: =IF(AND(B18<>"",A19<>""),_xlfn.TEXTJOIN("_",TRUE,B$1,$A19),"") -> axe_reload_delay | C19: =IF(AND(C18<>"",B19<>""),_xlfn.TEXTJOIN("_",TRUE,C$1,$A19),"") -> grenadelauncher_reload_delay | D19: =IF(AND(D18<>"",C19<>""),_xlfn.TEXTJOIN("_",TRUE,D$1,$A19),"") -> lightninggun_reload_delay | E19: =IF(AND(E18<>"",D19<>""),_xlfn.TEXTJOIN("_",TRUE,E$1,$A19),"") -> nailgun_reload_delay | F19: =IF(AND(F18<>"",E19<>""),_xlfn.TEXTJOIN("_",TRUE,F$1,$A19),"") -> perforator_reload_delay | G19: =IF(AND(G18<>"",F19<>""),_xlfn.TEXTJOIN("_",TRUE,G$1,$A19),"") -> rocketlauncher_reload_delay | H19: =IF(AND(H18<>"",G19<>""),_xlfn.TEXTJOIN("_",TRUE,H$1,$A19),"") -> shotgun_reload_delay | I19: =IF(AND(I18<>"",H19<>""),_xlfn.TEXTJOIN("_",TRUE,I$1,$A19),"") -> soldiershotgun_reload_delay | ... Z19: =IF(AND(Z18<>"",Y19<>""),_xlfn.TEXTJOIN("_",TRUE,Z$1,$A19),"")
A20: reload_delay_first | B20: =IF(AND(B19<>"",A20<>""),_xlfn.TEXTJOIN("_",TRUE,B$1,$A20),"") -> axe_reload_delay_first | C20: =IF(AND(C19<>"",B20<>""),_xlfn.TEXTJOIN("_",TRUE,C$1,$A20),"") -> grenadelauncher_reload_delay_first | D20: =IF(AND(D19<>"",C20<>""),_xlfn.TEXTJOIN("_",TRUE,D$1,$A20),"") -> lightninggun_reload_delay_first | E20: =IF(AND(E19<>"",D20<>""),_xlfn.TEXTJOIN("_",TRUE,E$1,$A20),"") -> nailgun_reload_delay_first | F20: =IF(AND(F19<>"",E20<>""),_xlfn.TEXTJOIN("_",TRUE,F$1,$A20),"") -> perforator_reload_delay_first | G20: =IF(AND(G19<>"",F20<>""),_xlfn.TEXTJOIN("_",TRUE,G$1,$A20),"") -> rocketlauncher_reload_delay_first | H20: =IF(AND(H19<>"",G20<>""),_xlfn.TEXTJOIN("_",TRUE,H$1,$A20),"") -> shotgun_reload_delay_first | I20: =IF(AND(I19<>"",H20<>""),_xlfn.TEXTJOIN("_",TRUE,I$1,$A20),"") -> soldiershotgun_reload_delay_first | ... Z20: =IF(AND(Z19<>"",Y20<>""),_xlfn.TEXTJOIN("_",TRUE,Z$1,$A20),"")
A21: reload_max_ammo | B21: =IF(AND(B20<>"",A21<>""),_xlfn.TEXTJOIN("_",TRUE,B$1,$A21),"") -> axe_reload_max_ammo | C21: =IF(AND(C20<>"",B21<>""),_xlfn.TEXTJOIN("_",TRUE,C$1,$A21),"") -> grenadelauncher_reload_max_ammo | D21: =IF(AND(D20<>"",C21<>""),_xlfn.TEXTJOIN("_",TRUE,D$1,$A21),"") -> lightninggun_reload_max_ammo | E21: =IF(AND(E20<>"",D21<>""),_xlfn.TEXTJOIN("_",TRUE,E$1,$A21),"") -> nailgun_reload_max_ammo | F21: =IF(AND(F20<>"",E21<>""),_xlfn.TEXTJOIN("_",TRUE,F$1,$A21),"") -> perforator_reload_max_ammo | G21: =IF(AND(G20<>"",F21<>""),_xlfn.TEXTJOIN("_",TRUE,G$1,$A21),"") -> rocketlauncher_reload_max_ammo | H21: =IF(AND(H20<>"",G21<>""),_xlfn.TEXTJOIN("_",TRUE,H$1,$A21),"") -> shotgun_reload_max_ammo | I21: =IF(AND(I20<>"",H21<>""),_xlfn.TEXTJOIN("_",TRUE,I$1,$A21),"") -> soldiershotgun_reload_max_ammo | ... Z21: =IF(AND(Z20<>"",Y21<>""),_xlfn.TEXTJOIN("_",TRUE,Z$1,$A21),"")
A22: sfx_fire | B22: =IF(AND(B21<>"",A22<>""),_xlfn.TEXTJOIN("_",TRUE,B$1,$A22),"") -> axe_sfx_fire | C22: =IF(AND(C21<>"",B22<>""),_xlfn.TEXTJOIN("_",TRUE,C$1,$A22),"") -> grenadelauncher_sfx_fire | D22: =IF(AND(D21<>"",C22<>""),_xlfn.TEXTJOIN("_",TRUE,D$1,$A22),"") -> lightninggun_sfx_fire | E22: =IF(AND(E21<>"",D22<>""),_xlfn.TEXTJOIN("_",TRUE,E$1,$A22),"") -> nailgun_sfx_fire | F22: =IF(AND(F21<>"",E22<>""),_xlfn.TEXTJOIN("_",TRUE,F$1,$A22),"") -> perforator_sfx_fire | G22: =IF(AND(G21<>"",F22<>""),_xlfn.TEXTJOIN("_",TRUE,G$1,$A22),"") -> rocketlauncher_sfx_fire | H22: =IF(AND(H21<>"",G22<>""),_xlfn.TEXTJOIN("_",TRUE,H$1,$A22),"") -> shotgun_sfx_fire | I22: =IF(AND(I21<>"",H22<>""),_xlfn.TEXTJOIN("_",TRUE,I$1,$A22),"") -> soldiershotgun_sfx_fire | ... Z22: =IF(AND(Z21<>"",Y22<>""),_xlfn.TEXTJOIN("_",TRUE,Z$1,$A22),"")
A23: shot_count | B23: =IF(AND(B22<>"",A23<>""),_xlfn.TEXTJOIN("_",TRUE,B$1,$A23),"") -> axe_shot_count | C23: =IF(AND(C22<>"",B23<>""),_xlfn.TEXTJOIN("_",TRUE,C$1,$A23),"") -> grenadelauncher_shot_count | D23: =IF(AND(D22<>"",C23<>""),_xlfn.TEXTJOIN("_",TRUE,D$1,$A23),"") -> lightninggun_shot_count | E23: =IF(AND(E22<>"",D23<>""),_xlfn.TEXTJOIN("_",TRUE,E$1,$A23),"") -> nailgun_shot_count | F23: =IF(AND(F22<>"",E23<>""),_xlfn.TEXTJOIN("_",TRUE,F$1,$A23),"") -> perforator_shot_count | G23: =IF(AND(G22<>"",F23<>""),_xlfn.TEXTJOIN("_",TRUE,G$1,$A23),"") -> rocketlauncher_shot_count | H23: =IF(AND(H22<>"",G23<>""),_xlfn.TEXTJOIN("_",TRUE,H$1,$A23),"") -> shotgun_shot_count | I23: =IF(AND(I22<>"",H23<>""),_xlfn.TEXTJOIN("_",TRUE,I$1,$A23),"") -> soldiershotgun_shot_count | ... Z23: =IF(AND(Z22<>"",Y23<>""),_xlfn.TEXTJOIN("_",TRUE,Z$1,$A23),"")
A24: splash_dmg | B24: =IF(AND(B23<>"",A24<>""),_xlfn.TEXTJOIN("_",TRUE,B$1,$A24),"") -> axe_splash_dmg | C24: =IF(AND(C23<>"",B24<>""),_xlfn.TEXTJOIN("_",TRUE,C$1,$A24),"") -> grenadelauncher_splash_dmg | D24: =IF(AND(D23<>"",C24<>""),_xlfn.TEXTJOIN("_",TRUE,D$1,$A24),"") -> lightninggun_splash_dmg | E24: =IF(AND(E23<>"",D24<>""),_xlfn.TEXTJOIN("_",TRUE,E$1,$A24),"") -> nailgun_splash_dmg | F24: =IF(AND(F23<>"",E24<>""),_xlfn.TEXTJOIN("_",TRUE,F$1,$A24),"") -> perforator_splash_dmg | G24: =IF(AND(G23<>"",F24<>""),_xlfn.TEXTJOIN("_",TRUE,G$1,$A24),"") -> rocketlauncher_splash_dmg | H24: =IF(AND(H23<>"",G24<>""),_xlfn.TEXTJOIN("_",TRUE,H$1,$A24),"") -> shotgun_splash_dmg | I24: =IF(AND(I23<>"",H24<>""),_xlfn.TEXTJOIN("_",TRUE,I$1,$A24),"") -> soldiershotgun_splash_dmg | ... Z24: =IF(AND(Z23<>"",Y24<>""),_xlfn.TEXTJOIN("_",TRUE,Z$1,$A24),"")
A25: spread | B25: =IF(AND(B24<>"",A25<>""),_xlfn.TEXTJOIN("_",TRUE,B$1,$A25),"") -> axe_spread | C25: =IF(AND(C24<>"",B25<>""),_xlfn.TEXTJOIN("_",TRUE,C$1,$A25),"") -> grenadelauncher_spread | D25: =IF(AND(D24<>"",C25<>""),_xlfn.TEXTJOIN("_",TRUE,D$1,$A25),"") -> lightninggun_spread | E25: =IF(AND(E24<>"",D25<>""),_xlfn.TEXTJOIN("_",TRUE,E$1,$A25),"") -> nailgun_spread | F25: =IF(AND(F24<>"",E25<>""),_xlfn.TEXTJOIN("_",TRUE,F$1,$A25),"") -> perforator_spread | G25: =IF(AND(G24<>"",F25<>""),_xlfn.TEXTJOIN("_",TRUE,G$1,$A25),"") -> rocketlauncher_spread | H25: =IF(AND(H24<>"",G25<>""),_xlfn.TEXTJOIN("_",TRUE,H$1,$A25),"") -> shotgun_spread | I25: =IF(AND(I24<>"",H25<>""),_xlfn.TEXTJOIN("_",TRUE,I$1,$A25),"") -> soldiershotgun_spread | ... Z25: =IF(AND(Z24<>"",Y25<>""),_xlfn.TEXTJOIN("_",TRUE,Z$1,$A25),"")
A26: timer | B26: =IF(AND(B25<>"",A26<>""),_xlfn.TEXTJOIN("_",TRUE,B$1,$A26),"") -> axe_timer | C26: =IF(AND(C25<>"",B26<>""),_xlfn.TEXTJOIN("_",TRUE,C$1,$A26),"") -> grenadelauncher_timer | D26: =IF(AND(D25<>"",C26<>""),_xlfn.TEXTJOIN("_",TRUE,D$1,$A26),"") -> lightninggun_timer | E26: =IF(AND(E25<>"",D26<>""),_xlfn.TEXTJOIN("_",TRUE,E$1,$A26),"") -> nailgun_timer | F26: =IF(AND(F25<>"",E26<>""),_xlfn.TEXTJOIN("_",TRUE,F$1,$A26),"") -> perforator_timer | G26: =IF(AND(G25<>"",F26<>""),_xlfn.TEXTJOIN("_",TRUE,G$1,$A26),"") -> rocketlauncher_timer | H26: =IF(AND(H25<>"",G26<>""),_xlfn.TEXTJOIN("_",TRUE,H$1,$A26),"") -> shotgun_timer | I26: =IF(AND(I25<>"",H26<>""),_xlfn.TEXTJOIN("_",TRUE,I$1,$A26),"") -> soldiershotgun_timer | ... Z26: =IF(AND(Z25<>"",Y26<>""),_xlfn.TEXTJOIN("_",TRUE,Z$1,$A26),"")
A27: vel | B27: =IF(AND(B26<>"",A27<>""),_xlfn.TEXTJOIN("_",TRUE,B$1,$A27),"") -> axe_vel | C27: =IF(AND(C26<>"",B27<>""),_xlfn.TEXTJOIN("_",TRUE,C$1,$A27),"") -> grenadelauncher_vel | D27: =IF(AND(D26<>"",C27<>""),_xlfn.TEXTJOIN("_",TRUE,D$1,$A27),"") -> lightninggun_vel | E27: =IF(AND(E26<>"",D27<>""),_xlfn.TEXTJOIN("_",TRUE,E$1,$A27),"") -> nailgun_vel | F27: =IF(AND(F26<>"",E27<>""),_xlfn.TEXTJOIN("_",TRUE,F$1,$A27),"") -> perforator_vel | G27: =IF(AND(G26<>"",F27<>""),_xlfn.TEXTJOIN("_",TRUE,G$1,$A27),"") -> rocketlauncher_vel | H27: =IF(AND(H26<>"",G27<>""),_xlfn.TEXTJOIN("_",TRUE,H$1,$A27),"") -> shotgun_vel | I27: =IF(AND(I26<>"",H27<>""),_xlfn.TEXTJOIN("_",TRUE,I$1,$A27),"") -> soldiershotgun_vel | ... Z27: =IF(AND(Z26<>"",Y27<>""),_xlfn.TEXTJOIN("_",TRUE,Z$1,$A27),"")
B28: =IF(AND(B27<>"",A28<>""),_xlfn.TEXTJOIN("_",TRUE,B$1,$A28),"") | C28: =IF(AND(C27<>"",B28<>""),_xlfn.TEXTJOIN("_",TRUE,C$1,$A28),"") | D28: =IF(AND(D27<>"",C28<>""),_xlfn.TEXTJOIN("_",TRUE,D$1,$A28),"") | E28: =IF(AND(E27<>"",D28<>""),_xlfn.TEXTJOIN("_",TRUE,E$1,$A28),"") | F28: =IF(AND(F27<>"",E28<>""),_xlfn.TEXTJOIN("_",TRUE,F$1,$A28),"") | G28: =IF(AND(G27<>"",F28<>""),_xlfn.TEXTJOIN("_",TRUE,G$1,$A28),"") | H28: =IF(AND(H27<>"",G28<>""),_xlfn.TEXTJOIN("_",TRUE,H$1,$A28),"") | I28: =IF(AND(I27<>"",H28<>""),_xlfn.TEXTJOIN("_",TRUE,I$1,$A28),"") | ... Z28: =IF(AND(Z27<>"",Y28<>""),_xlfn.TEXTJOIN("_",TRUE,Z$1,$A28),"")
B29: =IF(AND(B28<>"",A29<>""),_xlfn.TEXTJOIN("_",TRUE,B$1,$A29),"") | C29: =IF(AND(C28<>"",B29<>""),_xlfn.TEXTJOIN("_",TRUE,C$1,$A29),"") | D29: =IF(AND(D28<>"",C29<>""),_xlfn.TEXTJOIN("_",TRUE,D$1,$A29),"") | E29: =IF(AND(E28<>"",D29<>""),_xlfn.TEXTJOIN("_",TRUE,E$1,$A29),"") | F29: =IF(AND(F28<>"",E29<>""),_xlfn.TEXTJOIN("_",TRUE,F$1,$A29),"") | G29: =IF(AND(G28<>"",F29<>""),_xlfn.TEXTJOIN("_",TRUE,G$1,$A29),"") | H29: =IF(AND(H28<>"",G29<>""),_xlfn.TEXTJOIN("_",TRUE,H$1,$A29),"") | I29: =IF(AND(I28<>"",H29<>""),_xlfn.TEXTJOIN("_",TRUE,I$1,$A29),"") | ... Z29: =IF(AND(Z28<>"",Y29<>""),_xlfn.TEXTJOIN("_",TRUE,Z$1,$A29),"")
B30: =IF(AND(B29<>"",A30<>""),_xlfn.TEXTJOIN("_",TRUE,B$1,$A30),"") | C30: =IF(AND(C29<>"",B30<>""),_xlfn.TEXTJOIN("_",TRUE,C$1,$A30),"") | D30: =IF(AND(D29<>"",C30<>""),_xlfn.TEXTJOIN("_",TRUE,D$1,$A30),"") | E30: =IF(AND(E29<>"",D30<>""),_xlfn.TEXTJOIN("_",TRUE,E$1,$A30),"") | F30: =IF(AND(F29<>"",E30<>""),_xlfn.TEXTJOIN("_",TRUE,F$1,$A30),"") | G30: =IF(AND(G29<>"",F30<>""),_xlfn.TEXTJOIN("_",TRUE,G$1,$A30),"") | H30: =IF(AND(H29<>"",G30<>""),_xlfn.TEXTJOIN("_",TRUE,H$1,$A30),"") | I30: =IF(AND(I29<>"",H30<>""),_xlfn.TEXTJOIN("_",TRUE,I$1,$A30),"") | ... Z30: =IF(AND(Z29<>"",Y30<>""),_xlfn.TEXTJOIN("_",TRUE,Z$1,$A30),"")
B31: =IF(AND(B30<>"",A31<>""),_xlfn.TEXTJOIN("_",TRUE,B$1,$A31),"") | C31: =IF(AND(C30<>"",B31<>""),_xlfn.TEXTJOIN("_",TRUE,C$1,$A31),"") | D31: =IF(AND(D30<>"",C31<>""),_xlfn.TEXTJOIN("_",TRUE,D$1,$A31),"") | E31: =IF(AND(E30<>"",D31<>""),_xlfn.TEXTJOIN("_",TRUE,E$1,$A31),"") | F31: =IF(AND(F30<>"",E31<>""),_xlfn.TEXTJOIN("_",TRUE,F$1,$A31),"") | G31: =IF(AND(G30<>"",F31<>""),_xlfn.TEXTJOIN("_",TRUE,G$1,$A31),"") | H31: =IF(AND(H30<>"",G31<>""),_xlfn.TEXTJOIN("_",TRUE,H$1,$A31),"") | I31: =IF(AND(I30<>"",H31<>""),_xlfn.TEXTJOIN("_",TRUE,I$1,$A31),"") | ... Z31: =IF(AND(Z30<>"",Y31<>""),_xlfn.TEXTJOIN("_",TRUE,Z$1,$A31),"")
B32: =IF(AND(B31<>"",A32<>""),_xlfn.TEXTJOIN("_",TRUE,B$1,$A32),"") | C32: =IF(AND(C31<>"",B32<>""),_xlfn.TEXTJOIN("_",TRUE,C$1,$A32),"") | D32: =IF(AND(D31<>"",C32<>""),_xlfn.TEXTJOIN("_",TRUE,D$1,$A32),"") | E32: =IF(AND(E31<>"",D32<>""),_xlfn.TEXTJOIN("_",TRUE,E$1,$A32),"") | F32: =IF(AND(F31<>"",E32<>""),_xlfn.TEXTJOIN("_",TRUE,F$1,$A32),"") | G32: =IF(AND(G31<>"",F32<>""),_xlfn.TEXTJOIN("_",TRUE,G$1,$A32),"") | H32: =IF(AND(H31<>"",G32<>""),_xlfn.TEXTJOIN("_",TRUE,H$1,$A32),"") | I32: =IF(AND(I31<>"",H32<>""),_xlfn.TEXTJOIN("_",TRUE,I$1,$A32),"") | ... Z32: =IF(AND(Z31<>"",Y32<>""),_xlfn.TEXTJOIN("_",TRUE,Z$1,$A32),"")
B33: =IF(AND(B32<>"",A33<>""),_xlfn.TEXTJOIN("_",TRUE,B$1,$A33),"") | C33: =IF(AND(C32<>"",B33<>""),_xlfn.TEXTJOIN("_",TRUE,C$1,$A33),"") | D33: =IF(AND(D32<>"",C33<>""),_xlfn.TEXTJOIN("_",TRUE,D$1,$A33),"") | E33: =IF(AND(E32<>"",D33<>""),_xlfn.TEXTJOIN("_",TRUE,E$1,$A33),"") | F33: =IF(AND(F32<>"",E33<>""),_xlfn.TEXTJOIN("_",TRUE,F$1,$A33),"") | G33: =IF(AND(G32<>"",F33<>""),_xlfn.TEXTJOIN("_",TRUE,G$1,$A33),"") | H33: =IF(AND(H32<>"",G33<>""),_xlfn.TEXTJOIN("_",TRUE,H$1,$A33),"") | I33: =IF(AND(I32<>"",H33<>""),_xlfn.TEXTJOIN("_",TRUE,I$1,$A33),"") | ... Z33: =IF(AND(Z32<>"",Y33<>""),_xlfn.TEXTJOIN("_",TRUE,Z$1,$A33),"")
B34: =IF(AND(B33<>"",A34<>""),_xlfn.TEXTJOIN("_",TRUE,B$1,$A34),"") | C34: =IF(AND(C33<>"",B34<>""),_xlfn.TEXTJOIN("_",TRUE,C$1,$A34),"") | D34: =IF(AND(D33<>"",C34<>""),_xlfn.TEXTJOIN("_",TRUE,D$1,$A34),"") | E34: =IF(AND(E33<>"",D34<>""),_xlfn.TEXTJOIN("_",TRUE,E$1,$A34),"") | F34: =IF(AND(F33<>"",E34<>""),_xlfn.TEXTJOIN("_",TRUE,F$1,$A34),"") | G34: =IF(AND(G33<>"",F34<>""),_xlfn.TEXTJOIN("_",TRUE,G$1,$A34),"") | H34: =IF(AND(H33<>"",G34<>""),_xlfn.TEXTJOIN("_",TRUE,H$1,$A34),"") | I34: =IF(AND(I33<>"",H34<>""),_xlfn.TEXTJOIN("_",TRUE,I$1,$A34),"") | ... Z34: =IF(AND(Z33<>"",Y34<>""),_xlfn.TEXTJOIN("_",TRUE,Z$1,$A34),"")
B35: =IF(AND(B34<>"",A35<>""),_xlfn.TEXTJOIN("_",TRUE,B$1,$A35),"") | C35: =IF(AND(C34<>"",B35<>""),_xlfn.TEXTJOIN("_",TRUE,C$1,$A35),"") | D35: =IF(AND(D34<>"",C35<>""),_xlfn.TEXTJOIN("_",TRUE,D$1,$A35),"") | E35: =IF(AND(E34<>"",D35<>""),_xlfn.TEXTJOIN("_",TRUE,E$1,$A35),"") | F35: =IF(AND(F34<>"",E35<>""),_xlfn.TEXTJOIN("_",TRUE,F$1,$A35),"") | G35: =IF(AND(G34<>"",F35<>""),_xlfn.TEXTJOIN("_",TRUE,G$1,$A35),"") | H35: =IF(AND(H34<>"",G35<>""),_xlfn.TEXTJOIN("_",TRUE,H$1,$A35),"") | I35: =IF(AND(I34<>"",H35<>""),_xlfn.TEXTJOIN("_",TRUE,I$1,$A35),"") | ... Z35: =IF(AND(Z34<>"",Y35<>""),_xlfn.TEXTJOIN("_",TRUE,Z$1,$A35),"")
B36: =IF(AND(B35<>"",A36<>""),_xlfn.TEXTJOIN("_",TRUE,B$1,$A36),"") | C36: =IF(AND(C35<>"",B36<>""),_xlfn.TEXTJOIN("_",TRUE,C$1,$A36),"") | D36: =IF(AND(D35<>"",C36<>""),_xlfn.TEXTJOIN("_",TRUE,D$1,$A36),"") | E36: =IF(AND(E35<>"",D36<>""),_xlfn.TEXTJOIN("_",TRUE,E$1,$A36),"") | F36: =IF(AND(F35<>"",E36<>""),_xlfn.TEXTJOIN("_",TRUE,F$1,$A36),"") | G36: =IF(AND(G35<>"",F36<>""),_xlfn.TEXTJOIN("_",TRUE,G$1,$A36),"") | H36: =IF(AND(H35<>"",G36<>""),_xlfn.TEXTJOIN("_",TRUE,H$1,$A36),"") | I36: =IF(AND(I35<>"",H36<>""),_xlfn.TEXTJOIN("_",TRUE,I$1,$A36),"") | ... Z36: =IF(AND(Z35<>"",Y36<>""),_xlfn.TEXTJOIN("_",TRUE,Z$1,$A36),"")
B37: =IF(AND(B36<>"",A37<>""),_xlfn.TEXTJOIN("_",TRUE,B$1,$A37),"") | C37: =IF(AND(C36<>"",B37<>""),_xlfn.TEXTJOIN("_",TRUE,C$1,$A37),"") | D37: =IF(AND(D36<>"",C37<>""),_xlfn.TEXTJOIN("_",TRUE,D$1,$A37),"") | E37: =IF(AND(E36<>"",D37<>""),_xlfn.TEXTJOIN("_",TRUE,E$1,$A37),"") | F37: =IF(AND(F36<>"",E37<>""),_xlfn.TEXTJOIN("_",TRUE,F$1,$A37),"") | G37: =IF(AND(G36<>"",F37<>""),_xlfn.TEXTJOIN("_",TRUE,G$1,$A37),"") | H37: =IF(AND(H36<>"",G37<>""),_xlfn.TEXTJOIN("_",TRUE,H$1,$A37),"") | I37: =IF(AND(I36<>"",H37<>""),_xlfn.TEXTJOIN("_",TRUE,I$1,$A37),"") | ... Z37: =IF(AND(Z36<>"",Y37<>""),_xlfn.TEXTJOIN("_",TRUE,Z$1,$A37),"")
B38: =IF(AND(B37<>"",A38<>""),_xlfn.TEXTJOIN("_",TRUE,B$1,$A38),"") | C38: =IF(AND(C37<>"",B38<>""),_xlfn.TEXTJOIN("_",TRUE,C$1,$A38),"") | D38: =IF(AND(D37<>"",C38<>""),_xlfn.TEXTJOIN("_",TRUE,D$1,$A38),"") | E38: =IF(AND(E37<>"",D38<>""),_xlfn.TEXTJOIN("_",TRUE,E$1,$A38),"") | F38: =IF(AND(F37<>"",E38<>""),_xlfn.TEXTJOIN("_",TRUE,F$1,$A38),"") | G38: =IF(AND(G37<>"",F38<>""),_xlfn.TEXTJOIN("_",TRUE,G$1,$A38),"") | H38: =IF(AND(H37<>"",G38<>""),_xlfn.TEXTJOIN("_",TRUE,H$1,$A38),"") | I38: =IF(AND(I37<>"",H38<>""),_xlfn.TEXTJOIN("_",TRUE,I$1,$A38),"") | ... Z38: =IF(AND(Z37<>"",Y38<>""),_xlfn.TEXTJOIN("_",TRUE,Z$1,$A38),"")
B39: =IF(AND(B38<>"",A39<>""),_xlfn.TEXTJOIN("_",TRUE,B$1,$A39),"") | C39: =IF(AND(C38<>"",B39<>""),_xlfn.TEXTJOIN("_",TRUE,C$1,$A39),"") | D39: =IF(AND(D38<>"",C39<>""),_xlfn.TEXTJOIN("_",TRUE,D$1,$A39),"") | E39: =IF(AND(E38<>"",D39<>""),_xlfn.TEXTJOIN("_",TRUE,E$1,$A39),"") | F39: =IF(AND(F38<>"",E39<>""),_xlfn.TEXTJOIN("_",TRUE,F$1,$A39),"") | G39: =IF(AND(G38<>"",F39<>""),_xlfn.TEXTJOIN("_",TRUE,G$1,$A39),"") | H39: =IF(AND(H38<>"",G39<>""),_xlfn.TEXTJOIN("_",TRUE,H$1,$A39),"") | I39: =IF(AND(I38<>"",H39<>""),_xlfn.TEXTJOIN("_",TRUE,I$1,$A39),"") | ... Z39: =IF(AND(Z38<>"",Y39<>""),_xlfn.TEXTJOIN("_",TRUE,Z$1,$A39),"")
... B255: =IF(AND(B254<>"",A255<>""),_xlfn.TEXTJOIN("_",TRUE,B$1,$A255),"") | C255: =IF(AND(C254<>"",B255<>""),_xlfn.TEXTJOIN("_",TRUE,C$1,$A255),"") | D255: =IF(AND(D254<>"",C255<>""),_xlfn.TEXTJOIN("_",TRUE,D$1,$A255),"") | E255: =IF(AND(E254<>"",D255<>""),_xlfn.TEXTJOIN("_",TRUE,E$1,$A255),"") | F255: =IF(AND(F254<>"",E255<>""),_xlfn.TEXTJOIN("_",TRUE,F$1,$A255),"") | G255: =IF(AND(G254<>"",F255<>""),_xlfn.TEXTJOIN("_",TRUE,G$1,$A255),"") | H255: =IF(AND(H254<>"",G255<>""),_xlfn.TEXTJOIN("_",TRUE,H$1,$A255),"") | I255: =IF(AND(I254<>"",H255<>""),_xlfn.TEXTJOIN("_",TRUE,I$1,$A255),"") | ... Z255: =IF(AND(Z254<>"",Y255<>""),_xlfn.TEXTJOIN("_",TRUE,Z$1,$A255),"")

Sheet out
A1: autocvar(w | C1: , | E1: );

Sheet unformatted
A1: // rocket
A2: w_rocketlauncher_fn_fire | B2: "rocket"
A3: w_rocketlauncher_attack_delay | B3: 0.8
A4: w_rocketlauncher_shot_count | B4: 1
A5: w_rocketlauncher_dmg | B5: 120
A6: w_rocketlauncher_dmg_splash | B6: 120
A7: // spread
A8: w_rocketlauncher_fn_spread | B8: "oval"
A9: w_rocketlauncher_spread | B9: '0 0 0'
A10: // origin
A11: w_rocketlauncher_fn_origin | B11: "rocket"
A12: w_rocketlauncher_origin_angle_change | B12: 0
A13: w_rocketlauncher_origin_angle_offset | B13: 0
A14: w_rocketlauncher_origin_base_offset | B14: 0
A15: w_rocketlauncher_origin_circle_radius | B15: 0
A16: // ammo
A17: w_rocketlauncher_ammo_cost | B17: 0
A18: w_rocketlauncher_ammo_type | B18: "rocket"
A19: w_rocketlauncher_clip_size | B19: 0
A20: w_rocketlauncher_reload_delay | B20: 0
A21: w_rocketlauncher_reload_delay_first | B21: 0
A22: w_rocketlauncher_reload_max_ammo | B22: 0
A23: // projectile
A24: w_rocketlauncher_vel | B24: '1000 0 0'
A25: w_rocketlauncher_impart_vel | B25: '0 0 0'
A26: w_rocketlauncher_penetration_limit | B26: 0
A27: w_rocketlauncher_bounce | B27: 0
A28: w_rocketlauncher_timer | B28: 0
A29: // fx
A30: w_rocketlauncher_punch_angle | B30: '-2 0 0'
A31: w_rocketlauncher_sfx_fire | B31: "weapons/guncock.wav"

Sheet partialQc
A1: =IF(unformatted!$A1<>"",_xlfn.TEXTJOIN("",TRUE,"autocvar(",unformatted!$A1,", ",unformatted!$B1,");"),"") -> autocvar(// rocket, );
A2: =IF(unformatted!$A2<>"",_xlfn.TEXTJOIN("",TRUE,"autocvar(",unformatted!$A2,", ",unformatted!$B2,");"),"") -> autocvar(w_rocketlauncher_fn_fire, "rocket");
A3: =IF(unformatted!$A3<>"",_xlfn.TEXTJOIN("",TRUE,"autocvar(",unformatted!$A3,", ",unformatted!$B3,");"),"") -> autocvar(w_rocketlauncher_attack_delay, 0.8);
A4: =IF(unformatted!$A4<>"",_xlfn.TEXTJOIN("",TRUE,"autocvar(",unformatted!$A4,", ",unformatted!$B4,");"),"") -> autocvar(w_rocketlauncher_shot_count, 1);
A5: =IF(unformatted!$A5<>"",_xlfn.TEXTJOIN("",TRUE,"autocvar(",unformatted!$A5,", ",unformatted!$B5,");"),"") -> autocvar(w_rocketlauncher_dmg, 120);
A6: =IF(unformatted!$A6<>"",_xlfn.TEXTJOIN("",TRUE,"autocvar(",unformatted!$A6,", ",unformatted!$B6,");"),"") -> autocvar(w_rocketlauncher_dmg_splash, 120);
A7: =IF(unformatted!$A7<>"",_xlfn.TEXTJOIN("",TRUE,"autocvar(",unformatted!$A7,", ",unformatted!$B7,");"),"") -> autocvar(// spread, );
A8: =IF(unformatted!$A8<>"",_xlfn.TEXTJOIN("",TRUE,"autocvar(",unformatted!$A8,", ",unformatted!$B8,");"),"") -> autocvar(w_rocketlauncher_fn_spread, "oval");
A9: =IF(unformatted!$A9<>"",_xlfn.TEXTJOIN("",TRUE,"autocvar(",unformatted!$A9,", ",unformatted!$B9,");"),"") -> autocvar(w_rocketlauncher_spread, '0 0 0');
A10: =IF(unformatted!$A10<>"",_xlfn.TEXTJOIN("",TRUE,"autocvar(",unformatted!$A10,", ",unformatted!$B10,");"),"") -> autocvar(// origin, );
A11: =IF(unformatted!$A11<>"",_xlfn.TEXTJOIN("",TRUE,"autocvar(",unformatted!$A11,", ",unformatted!$B11,");"),"") -> autocvar(w_rocketlauncher_fn_origin, "rocket");
A12: =IF(unformatted!$A12<>"",_xlfn.TEXTJOIN("",TRUE,"autocvar(",unformatted!$A12,", ",unformatted!$B12,");"),"") -> autocvar(w_rocketlauncher_origin_angle_change, 0);
... A255: =IF(unformatted!$A255<>"",_xlfn.TEXTJOIN("",TRUE,"autocvar(",unformatted!$A255,", ",unformatted!$B255,");"),"")

Sheet formattedQc
A1: =IF(unformatted!$A1<>"",IF(ISERR(FIND("//",partialQc!$A1)),partialQc!$A1,unformatted!$A1),"") -> // rocket
A2: =IF(unformatted!$A2<>"",IF(ISERR(FIND("//",partialQc!$A2)),partialQc!$A2,unformatted!$A2),"") -> autocvar(w_rocketlauncher_fn_fire, "rocket");
A3: =IF(unformatted!$A3<>"",IF(ISERR(FIND("//",partialQc!$A3)),partialQc!$A3,unformatted!$A3),"") -> autocvar(w_rocketlauncher_attack_delay, 0.8);
A4: =IF(unformatted!$A4<>"",IF(ISERR(FIND("//",partialQc!$A4)),partialQc!$A4,unformatted!$A4),"") -> autocvar(w_rocketlauncher_shot_count, 1);
A5: =IF(unformatted!$A5<>"",IF(ISERR(FIND("//",partialQc!$A5)),partialQc!$A5,unformatted!$A5),"") -> autocvar(w_rocketlauncher_dmg, 120);
A6: =IF(unformatted!$A6<>"",IF(ISERR(FIND("//",partialQc!$A6)),partialQc!$A6,unformatted!$A6),"") -> autocvar(w_rocketlauncher_dmg_splash, 120);
A7: =IF(unformatted!$A7<>"",IF(ISERR(FIND("//",partialQc!$A7)),partialQc!$A7,unformatted!$A7),"") -> // spread
A8: =IF(unformatted!$A8<>"",IF(ISERR(FIND("//",partialQc!$A8)),partialQc!$A8,unformatted!$A8),"") -> autocvar(w_rocketlauncher_fn_spread, "oval");
A9: =IF(unformatted!$A9<>"",IF(ISERR(FIND("//",partialQc!$A9)),partialQc!$A9,unformatted!$A9),"") -> autocvar(w_rocketlauncher_spread, '0 0 0');
A10: =IF(unformatted!$A10<>"",IF(ISERR(FIND("//",partialQc!$A10)),partialQc!$A10,unformatted!$A10),"") -> // origin
A11: =IF(unformatted!$A11<>"",IF(ISERR(FIND("//",partialQc!$A11)),partialQc!$A11,unformatted!$A11),"") -> autocvar(w_rocketlauncher_fn_origin, "rocket");
A12: =IF(unformatted!$A12<>"",IF(ISERR(FIND("//",partialQc!$A12)),partialQc!$A12,unformatted!$A12),"") -> autocvar(w_rocketlauncher_origin_angle_change, 0);
... A255: =IF(unformatted!$A255<>"",IF(ISERR(FIND("//",partialQc!$A255)),partialQc!$A255,unformatted!$A255),"")

Sheet partialRc
A1: =IF(unformatted!$A1<>"",_xlfn.TEXTJOIN("",TRUE,"set ",unformatted!$A1," ",unformatted!$B1),"") -> set // rocket
A2: =IF(unformatted!$A2<>"",_xlfn.TEXTJOIN("",TRUE,"set ",unformatted!$A2," ",unformatted!$B2),"") -> set w_rocketlauncher_fn_fire "rocket"
A3: =IF(unformatted!$A3<>"",_xlfn.TEXTJOIN("",TRUE,"set ",unformatted!$A3," ",unformatted!$B3),"") -> set w_rocketlauncher_attack_delay 0.8
A4: =IF(unformatted!$A4<>"",_xlfn.TEXTJOIN("",TRUE,"set ",unformatted!$A4," ",unformatted!$B4),"") -> set w_rocketlauncher_shot_count 1
A5: =IF(unformatted!$A5<>"",_xlfn.TEXTJOIN("",TRUE,"set ",unformatted!$A5," ",unformatted!$B5),"") -> set w_rocketlauncher_dmg 120
A6: =IF(unformatted!$A6<>"",_xlfn.TEXTJOIN("",TRUE,"set ",unformatted!$A6," ",unformatted!$B6),"") -> set w_rocketlauncher_dmg_splash 120
A7: =IF(unformatted!$A7<>"",_xlfn.TEXTJOIN("",TRUE,"set ",unformatted!$A7," ",unformatted!$B7),"") -> set // spread
A8: =IF(unformatted!$A8<>"",_xlfn.TEXTJOIN("",TRUE,"set ",unformatted!$A8," ",unformatted!$B8),"") -> set w_rocketlauncher_fn_spread "oval"
A9: =IF(unformatted!$A9<>"",_xlfn.TEXTJOIN("",TRUE,"set ",unformatted!$A9," ",unformatted!$B9),"") -> set w_rocketlauncher_spread '0 0 0'
A10: =IF(unformatted!$A10<>"",_xlfn.TEXTJOIN("",TRUE,"set ",unformatted!$A10," ",unformatted!$B10),"") -> set // origin
A11: =IF(unformatted!$A11<>"",_xlfn.TEXTJOIN("",TRUE,"set ",unformatted!$A11," ",unformatted!$B11),"") -> set w_rocketlauncher_fn_origin "rocket"
A12: =IF(unformatted!$A12<>"",_xlfn.TEXTJOIN("",TRUE,"set ",unformatted!$A12," ",unformatted!$B12),"") -> set w_rocketlauncher_origin_angle_change 0
... A255: =IF(unformatted!$A255<>"",_xlfn.TEXTJOIN("",TRUE,"set ",unformatted!$A255," ",unformatted!$B255),"")

Sheet formattedRc
A1: =IF(unformatted!$A1<>"",IF(ISERR(FIND("//",partialQc!$A1)),partialQc!$A1,unformatted!$A1),"") -> // rocket
A2: =IF(unformatted!$A2<>"",IF(ISERR(FIND("//",partialQc!$A2)),partialRc!$A2,unformatted!$A2),"") -> set w_rocketlauncher_fn_fire "rocket"
A3: =IF(unformatted!$A3<>"",IF(ISERR(FIND("//",partialQc!$A3)),partialRc!$A3,unformatted!$A3),"") -> set w_rocketlauncher_attack_delay 0.8
A4: =IF(unformatted!$A4<>"",IF(ISERR(FIND("//",partialQc!$A4)),partialRc!$A4,unformatted!$A4),"") -> set w_rocketlauncher_shot_count 1
A5: =IF(unformatted!$A5<>"",IF(ISERR(FIND("//",partialQc!$A5)),partialRc!$A5,unformatted!$A5),"") -> set w_rocketlauncher_dmg 120
A6: =IF(unformatted!$A6<>"",IF(ISERR(FIND("//",partialQc!$A6)),partialRc!$A6,unformatted!$A6),"") -> set w_rocketlauncher_dmg_splash 120
A7: =IF(unformatted!$A7<>"",IF(ISERR(FIND("//",partialQc!$A7)),partialRc!$A7,unformatted!$A7),"") -> // spread
A8: =IF(unformatted!$A8<>"",IF(ISERR(FIND("//",partialQc!$A8)),partialRc!$A8,unformatted!$A8),"") -> set w_rocketlauncher_fn_spread "oval"
A9: =IF(unformatted!$A9<>"",IF(ISERR(FIND("//",partialQc!$A9)),partialRc!$A9,unformatted!$A9),"") -> set w_rocketlauncher_spread '0 0 0'
A10: =IF(unformatted!$A10<>"",IF(ISERR(FIND("//",partialQc!$A10)),partialRc!$A10,unformatted!$A10),"") -> // origin
A11: =IF(unformatted!$A11<>"",IF(ISERR(FIND("//",partialQc!$A11)),partialRc!$A11,unformatted!$A11),"") -> set w_rocketlauncher_fn_origin "rocket"
A12: =IF(unformatted!$A12<>"",IF(ISERR(FIND("//",partialQc!$A12)),partialRc!$A12,unformatted!$A12),"") -> set w_rocketlauncher_origin_angle_change 0
A13: =IF(unformatted!$A13<>"",IF(ISERR(FIND("//",partialQc!$A13)),partialRc!$A13,unformatted!$A13),"") -> set w_rocketlauncher_origin_angle_offset 0
... A31: =IF(unformatted!$A31<>"",IF(ISERR(FIND("//",partialQc!$A31)),partialRc!$A31,unformatted!$A31),"") -> set w_rocketlauncher_sfx_fire "weapons/guncock.wav"
A32: =IF(unformatted!$A32<>"",IF(ISERR(FIND("//",partialQc!$A32)),partialRc!$A32,unformatted!$A32),"") | C32: =IF(unformatted!$A32<>"",IF(ISERR(FIND("//",partialQc!$A32)),partialQc!$A32,unformatted!$A32),"")
A33: =IF(unformatted!$A33<>"",IF(ISERR(FIND("//",partialQc!$A33)),partialRc!$A33,unformatted!$A33),"") | C33: =IF(unformatted!$A33<>"",IF(ISERR(FIND("//",partialQc!$A33)),partialQc!$A33,unformatted!$A33),"")
A34: =IF(unformatted!$A34<>"",IF(ISERR(FIND("//",partialQc!$A34)),partialRc!$A34,unformatted!$A34),"") | C34: =IF(unformatted!$A34<>"",IF(ISERR(FIND("//",partialQc!$A34)),partialQc!$A34,unformatted!$A34),"")
A35: =IF(unformatted!$A35<>"",IF(ISERR(FIND("//",partialQc!$A35)),partialRc!$A35,unformatted!$A35),"") | C35: =IF(unformatted!$A35<>"",IF(ISERR(FIND("//",partialQc!$A35)),partialQc!$A35,unformatted!$A35),"")
A36: =IF(unformatted!$A36<>"",IF(ISERR(FIND("//",partialQc!$A36)),partialRc!$A36,unformatted!$A36),"") | C36: =IF(unformatted!$A36<>"",IF(ISERR(FIND("//",partialQc!$A36)),partialQc!$A36,unformatted!$A36),"")
A37: =IF(unformatted!$A37<>"",IF(ISERR(FIND("//",partialQc!$A37)),partialRc!$A37,unformatted!$A37),"") | C37: =IF(unformatted!$A37<>"",IF(ISERR(FIND("//",partialQc!$A37)),partialQc!$A37,unformatted!$A37),"")
A38: =IF(unformatted!$A38<>"",IF(ISERR(FIND("//",partialQc!$A38)),partialRc!$A38,unformatted!$A38),"") | C38: =IF(unformatted!$A38<>"",IF(ISERR(FIND("//",partialQc!$A38)),partialQc!$A38,unformatted!$A38),"")
A39: =IF(unformatted!$A39<>"",IF(ISERR(FIND("//",partialQc!$A39)),partialRc!$A39,unformatted!$A39),"") | C39: =IF(unformatted!$A39<>"",IF(ISERR(FIND("//",partialQc!$A39)),partialQc!$A39,unformatted!$A39),"")
A40: =IF(unformatted!$A40<>"",IF(ISERR(FIND("//",partialQc!$A40)),partialRc!$A40,unformatted!$A40),"") | C40: =IF(unformatted!$A40<>"",IF(ISERR(FIND("//",partialQc!$A40)),partialQc!$A40,unformatted!$A40),"")
A41: =IF(unformatted!$A41<>"",IF(ISERR(FIND("//",partialQc!$A41)),partialRc!$A41,unformatted!$A41),"") | C41: =IF(unformatted!$A41<>"",IF(ISERR(FIND("//",partialQc!$A41)),partialQc!$A41,unformatted!$A41),"")
A42: =IF(unformatted!$A42<>"",IF(ISERR(FIND("//",partialQc!$A42)),partialRc!$A42,unformatted!$A42),"") | C42: =IF(unformatted!$A42<>"",IF(ISERR(FIND("//",partialQc!$A42)),partialQc!$A42,unformatted!$A42),"")
A43: =IF(unformatted!$A43<>"",IF(ISERR(FIND("//",partialQc!$A43)),partialRc!$A43,unformatted!$A43),"") | C43: =IF(unformatted!$A43<>"",IF(ISERR(FIND("//",partialQc!$A43)),partialQc!$A43,unformatted!$A43),"")
... A56: =IF(unformatted!$A56<>"",IF(ISERR(FIND("//",partialQc!$A56)),partialRc!$A56,unformatted!$A56),"") | C56: =IF(unformatted!$A56<>"",IF(ISERR(FIND("//",partialQc!$A56)),partialQc!$A56,unformatted!$A56),"")
A57: =IF(unformatted!$A57<>"",IF(ISERR(FIND("//",partialQc!$A57)),partialRc!$A57,unformatted!$A57),"")
A58: =IF(unformatted!$A58<>"",IF(ISERR(FIND("//",partialQc!$A58)),partialRc!$A58,unformatted!$A58),"")
A59: =IF(unformatted!$A59<>"",IF(ISERR(FIND("//",partialQc!$A59)),partialRc!$A59,unformatted!$A59),"")
A60: =IF(unformatted!$A60<>"",IF(ISERR(FIND("//",partialQc!$A60)),partialRc!$A60,unformatted!$A60),"")
A61: =IF(unformatted!$A61<>"",IF(ISERR(FIND("//",partialQc!$A61)),partialRc!$A61,unformatted!$A61),"")
A62: =IF(unformatted!$A62<>"",IF(ISERR(FIND("//",partialQc!$A62)),partialRc!$A62,unformatted!$A62),"")
A63: =IF(unformatted!$A63<>"",IF(ISERR(FIND("//",partialQc!$A63)),partialRc!$A63,unformatted!$A63),"")
A64: =IF(unformatted!$A64<>"",IF(ISERR(FIND("//",partialQc!$A64)),partialRc!$A64,unformatted!$A64),"")
A65: =IF(unformatted!$A65<>"",IF(ISERR(FIND("//",partialQc!$A65)),partialRc!$A65,unformatted!$A65),"")
A66: =IF(unformatted!$A66<>"",IF(ISERR(FIND("//",partialQc!$A66)),partialRc!$A66,unformatted!$A66),"")
A67: =IF(unformatted!$A67<>"",IF(ISERR(FIND("//",partialQc!$A67)),partialRc!$A67,unformatted!$A67),"")
A68: =IF(unformatted!$A68<>"",IF(ISERR(FIND("//",partialQc!$A68)),partialRc!$A68,unformatted!$A68),"")
... A255: =IF(unformatted!$A255<>"",IF(ISERR(FIND("//",partialQc!$A255)),partialRc!$A255,unformatted!$A255),"")
